{
 "cells": [
  {
   "cell_type": "code",
   "execution_count": 9,
   "metadata": {},
   "outputs": [],
   "source": [
    "import tensorflow as tf\n",
    "import tensorflow_gnn as tfgnn\n",
    "from importlib import reload\n",
    "from sys import modules\n",
    "from schema import TYPE_SPEC\n",
    "from generators import load_dataset_from_data"
   ]
  },
  {
   "cell_type": "code",
   "execution_count": 10,
   "metadata": {},
   "outputs": [],
   "source": [
    "reload(modules[\"schema\"])\n",
    "from schema import TYPE_SPEC\n",
    "spec = TYPE_SPEC[\"mnist_graph\"]"
   ]
  },
  {
   "cell_type": "code",
   "execution_count": 11,
   "metadata": {},
   "outputs": [
    {
     "name": "stdout",
     "output_type": "stream",
     "text": [
      "Model: \"gnn\"\n",
      "_________________________________________________________________\n",
      " Layer (type)                Output Shape              Param #   \n",
      "=================================================================\n",
      " input_2 (InputLayer)        [()]                      0         \n",
      "                                                                 \n",
      " graph_update_1 (GraphUpdate  ()                       1184      \n",
      " )                                                               \n",
      "                                                                 \n",
      " readout_1 (Readout)         (784, 32)                 0         \n",
      "                                                                 \n",
      " dense_2 (Dense)             (784, 120)                3960      \n",
      "                                                                 \n",
      " dense_3 (Dense)             (784, 10)                 1210      \n",
      "                                                                 \n",
      "=================================================================\n",
      "Total params: 6,354\n",
      "Trainable params: 6,354\n",
      "Non-trainable params: 0\n",
      "_________________________________________________________________\n"
     ]
    }
   ],
   "source": [
    "input = tf.keras.layers.Input(type_spec=spec)\n",
    "gnn = tfgnn.keras.ConvGNNBuilder(\n",
    "    lambda edge: tfgnn.keras.layers.SimpleConvolution(\n",
    "        tf.keras.layers.Dense(32)\n",
    "    ),\n",
    "    lambda node: tfgnn.keras.layers.NextStateFromConcat(\n",
    "        tf.keras.layers.Dense(32),\n",
    "    ),\n",
    "    )\n",
    "hidden = gnn.Convolve()(input)\n",
    "# hidden = tfgnn.keras.layers.Pool(\n",
    "#     tag=tfgnn.SOURCE,\n",
    "#     edge_set_name=\"connected\",\n",
    "#     reduce_type=\"sum\"\n",
    "# )(hidden)\n",
    "hidden = tfgnn.keras.layers.Readout(node_set_name=\"pixel\")(hidden)\n",
    "hidden = tf.keras.layers.Dense(120, activation=\"tanh\")(hidden)\n",
    "output = tf.keras.layers.Dense(10, activation=\"softmax\")(hidden)\n",
    "\n",
    "model = tf.keras.Model(input, output, name = \"gnn\")\n",
    "model.summary()"
   ]
  },
  {
   "cell_type": "code",
   "execution_count": 12,
   "metadata": {},
   "outputs": [],
   "source": [
    "model.compile(optimizer=\"adam\", loss=tf.keras.losses.categorical_crossentropy, metrics=[\"accuracy\"])"
   ]
  },
  {
   "cell_type": "code",
   "execution_count": 13,
   "metadata": {},
   "outputs": [],
   "source": [
    "reload(modules[\"generators\"])\n",
    "from generators import load_dataset_from_data\n",
    "\n",
    "(trn_img, trn_lbl), _ = tf.keras.datasets.mnist.load_data()\n",
    "trn_img = trn_img/255\n",
    "trn_graph = load_dataset_from_data(trn_img, trn_lbl, 32, spec)"
   ]
  },
  {
   "cell_type": "code",
   "execution_count": 14,
   "metadata": {},
   "outputs": [
    {
     "name": "stdout",
     "output_type": "stream",
     "text": [
      "<class 'tensorflow.python.data.ops.dataset_ops.CacheDataset'>\n"
     ]
    },
    {
     "name": "stderr",
     "output_type": "stream",
     "text": [
      "2022-03-01 23:47:30.268638: W tensorflow/core/kernels/data/cache_dataset_ops.cc:768] The calling iterator did not fully read the dataset being cached. In order to avoid unexpected truncation of the dataset, the partially cached contents of the dataset  will be discarded. This can happen if you have an input pipeline similar to `dataset.cache().take(k).repeat()`. You should use `dataset.take(k).cache().repeat()` instead.\n"
     ]
    },
    {
     "name": "stdout",
     "output_type": "stream",
     "text": [
      "1\n"
     ]
    }
   ],
   "source": [
    "print(type(trn_graph))\n",
    "print(len(list(trn_graph.take(1))))"
   ]
  },
  {
   "cell_type": "code",
   "execution_count": 15,
   "metadata": {},
   "outputs": [
    {
     "name": "stdout",
     "output_type": "stream",
     "text": [
      "Epoch 1/10\n"
     ]
    },
    {
     "ename": "ValueError",
     "evalue": "in user code:\n\n    File \"/home/thomas/Documents/tfgnn-mnist/env/lib/python3.9/site-packages/keras/engine/training.py\", line 1021, in train_function  *\n        return step_function(self, iterator)\n    File \"/home/thomas/Documents/tfgnn-mnist/env/lib/python3.9/site-packages/keras/engine/training.py\", line 1010, in step_function  **\n        outputs = model.distribute_strategy.run(run_step, args=(data,))\n    File \"/home/thomas/Documents/tfgnn-mnist/env/lib/python3.9/site-packages/keras/engine/training.py\", line 1000, in run_step  **\n        outputs = model.train_step(data)\n    File \"/home/thomas/Documents/tfgnn-mnist/env/lib/python3.9/site-packages/keras/engine/training.py\", line 860, in train_step\n        loss = self.compute_loss(x, y, y_pred, sample_weight)\n    File \"/home/thomas/Documents/tfgnn-mnist/env/lib/python3.9/site-packages/keras/engine/training.py\", line 918, in compute_loss\n        return self.compiled_loss(\n    File \"/home/thomas/Documents/tfgnn-mnist/env/lib/python3.9/site-packages/keras/engine/compile_utils.py\", line 201, in __call__\n        loss_value = loss_obj(y_t, y_p, sample_weight=sw)\n    File \"/home/thomas/Documents/tfgnn-mnist/env/lib/python3.9/site-packages/keras/losses.py\", line 141, in __call__\n        losses = call_fn(y_true, y_pred)\n    File \"/home/thomas/Documents/tfgnn-mnist/env/lib/python3.9/site-packages/keras/losses.py\", line 245, in call  **\n        return ag_fn(y_true, y_pred, **self._fn_kwargs)\n    File \"/home/thomas/Documents/tfgnn-mnist/env/lib/python3.9/site-packages/keras/losses.py\", line 1789, in categorical_crossentropy\n        return backend.categorical_crossentropy(\n    File \"/home/thomas/Documents/tfgnn-mnist/env/lib/python3.9/site-packages/keras/backend.py\", line 5083, in categorical_crossentropy\n        target.shape.assert_is_compatible_with(output.shape)\n\n    ValueError: Shapes (32, 1) and (25088, 10) are incompatible\n",
     "output_type": "error",
     "traceback": [
      "\u001b[0;31m---------------------------------------------------------------------------\u001b[0m",
      "\u001b[0;31mValueError\u001b[0m                                Traceback (most recent call last)",
      "\u001b[1;32m/home/thomas/Documents/tfgnn-mnist/Main.ipynb Cell 7'\u001b[0m in \u001b[0;36m<cell line: 1>\u001b[0;34m()\u001b[0m\n\u001b[0;32m----> <a href='vscode-notebook-cell:/home/thomas/Documents/tfgnn-mnist/Main.ipynb#ch0000006?line=0'>1</a>\u001b[0m model\u001b[39m.\u001b[39;49mfit(trn_graph, epochs\u001b[39m=\u001b[39;49m\u001b[39m10\u001b[39;49m)\n",
      "File \u001b[0;32m~/Documents/tfgnn-mnist/env/lib/python3.9/site-packages/keras/utils/traceback_utils.py:67\u001b[0m, in \u001b[0;36mfilter_traceback.<locals>.error_handler\u001b[0;34m(*args, **kwargs)\u001b[0m\n\u001b[1;32m     <a href='file:///~/Documents/tfgnn-mnist/env/lib/python3.9/site-packages/keras/utils/traceback_utils.py?line=64'>65</a>\u001b[0m \u001b[39mexcept\u001b[39;00m \u001b[39mException\u001b[39;00m \u001b[39mas\u001b[39;00m e:  \u001b[39m# pylint: disable=broad-except\u001b[39;00m\n\u001b[1;32m     <a href='file:///~/Documents/tfgnn-mnist/env/lib/python3.9/site-packages/keras/utils/traceback_utils.py?line=65'>66</a>\u001b[0m   filtered_tb \u001b[39m=\u001b[39m _process_traceback_frames(e\u001b[39m.\u001b[39m__traceback__)\n\u001b[0;32m---> <a href='file:///~/Documents/tfgnn-mnist/env/lib/python3.9/site-packages/keras/utils/traceback_utils.py?line=66'>67</a>\u001b[0m   \u001b[39mraise\u001b[39;00m e\u001b[39m.\u001b[39mwith_traceback(filtered_tb) \u001b[39mfrom\u001b[39;00m \u001b[39mNone\u001b[39m\n\u001b[1;32m     <a href='file:///~/Documents/tfgnn-mnist/env/lib/python3.9/site-packages/keras/utils/traceback_utils.py?line=67'>68</a>\u001b[0m \u001b[39mfinally\u001b[39;00m:\n\u001b[1;32m     <a href='file:///~/Documents/tfgnn-mnist/env/lib/python3.9/site-packages/keras/utils/traceback_utils.py?line=68'>69</a>\u001b[0m   \u001b[39mdel\u001b[39;00m filtered_tb\n",
      "File \u001b[0;32m~/Documents/tfgnn-mnist/env/lib/python3.9/site-packages/tensorflow/python/framework/func_graph.py:1147\u001b[0m, in \u001b[0;36mfunc_graph_from_py_func.<locals>.autograph_handler\u001b[0;34m(*args, **kwargs)\u001b[0m\n\u001b[1;32m   <a href='file:///~/Documents/tfgnn-mnist/env/lib/python3.9/site-packages/tensorflow/python/framework/func_graph.py?line=1144'>1145</a>\u001b[0m \u001b[39mexcept\u001b[39;00m \u001b[39mException\u001b[39;00m \u001b[39mas\u001b[39;00m e:  \u001b[39m# pylint:disable=broad-except\u001b[39;00m\n\u001b[1;32m   <a href='file:///~/Documents/tfgnn-mnist/env/lib/python3.9/site-packages/tensorflow/python/framework/func_graph.py?line=1145'>1146</a>\u001b[0m   \u001b[39mif\u001b[39;00m \u001b[39mhasattr\u001b[39m(e, \u001b[39m\"\u001b[39m\u001b[39mag_error_metadata\u001b[39m\u001b[39m\"\u001b[39m):\n\u001b[0;32m-> <a href='file:///~/Documents/tfgnn-mnist/env/lib/python3.9/site-packages/tensorflow/python/framework/func_graph.py?line=1146'>1147</a>\u001b[0m     \u001b[39mraise\u001b[39;00m e\u001b[39m.\u001b[39mag_error_metadata\u001b[39m.\u001b[39mto_exception(e)\n\u001b[1;32m   <a href='file:///~/Documents/tfgnn-mnist/env/lib/python3.9/site-packages/tensorflow/python/framework/func_graph.py?line=1147'>1148</a>\u001b[0m   \u001b[39melse\u001b[39;00m:\n\u001b[1;32m   <a href='file:///~/Documents/tfgnn-mnist/env/lib/python3.9/site-packages/tensorflow/python/framework/func_graph.py?line=1148'>1149</a>\u001b[0m     \u001b[39mraise\u001b[39;00m\n",
      "\u001b[0;31mValueError\u001b[0m: in user code:\n\n    File \"/home/thomas/Documents/tfgnn-mnist/env/lib/python3.9/site-packages/keras/engine/training.py\", line 1021, in train_function  *\n        return step_function(self, iterator)\n    File \"/home/thomas/Documents/tfgnn-mnist/env/lib/python3.9/site-packages/keras/engine/training.py\", line 1010, in step_function  **\n        outputs = model.distribute_strategy.run(run_step, args=(data,))\n    File \"/home/thomas/Documents/tfgnn-mnist/env/lib/python3.9/site-packages/keras/engine/training.py\", line 1000, in run_step  **\n        outputs = model.train_step(data)\n    File \"/home/thomas/Documents/tfgnn-mnist/env/lib/python3.9/site-packages/keras/engine/training.py\", line 860, in train_step\n        loss = self.compute_loss(x, y, y_pred, sample_weight)\n    File \"/home/thomas/Documents/tfgnn-mnist/env/lib/python3.9/site-packages/keras/engine/training.py\", line 918, in compute_loss\n        return self.compiled_loss(\n    File \"/home/thomas/Documents/tfgnn-mnist/env/lib/python3.9/site-packages/keras/engine/compile_utils.py\", line 201, in __call__\n        loss_value = loss_obj(y_t, y_p, sample_weight=sw)\n    File \"/home/thomas/Documents/tfgnn-mnist/env/lib/python3.9/site-packages/keras/losses.py\", line 141, in __call__\n        losses = call_fn(y_true, y_pred)\n    File \"/home/thomas/Documents/tfgnn-mnist/env/lib/python3.9/site-packages/keras/losses.py\", line 245, in call  **\n        return ag_fn(y_true, y_pred, **self._fn_kwargs)\n    File \"/home/thomas/Documents/tfgnn-mnist/env/lib/python3.9/site-packages/keras/losses.py\", line 1789, in categorical_crossentropy\n        return backend.categorical_crossentropy(\n    File \"/home/thomas/Documents/tfgnn-mnist/env/lib/python3.9/site-packages/keras/backend.py\", line 5083, in categorical_crossentropy\n        target.shape.assert_is_compatible_with(output.shape)\n\n    ValueError: Shapes (32, 1) and (25088, 10) are incompatible\n"
     ]
    }
   ],
   "source": [
    "model.fit(trn_graph, epochs=10)"
   ]
  }
 ],
 "metadata": {
  "interpreter": {
   "hash": "d6cc1b48ae16f10eafcfc5d9834160e52b9d26f3378f7461b2bc28961673c20a"
  },
  "kernelspec": {
   "display_name": "Python 3.9.10 ('env': venv)",
   "language": "python",
   "name": "python3"
  },
  "language_info": {
   "codemirror_mode": {
    "name": "ipython",
    "version": 3
   },
   "file_extension": ".py",
   "mimetype": "text/x-python",
   "name": "python",
   "nbconvert_exporter": "python",
   "pygments_lexer": "ipython3",
   "version": "3.9.10"
  },
  "orig_nbformat": 4
 },
 "nbformat": 4,
 "nbformat_minor": 2
}
